Workbook

Sheet Как читать
A1: Цены билетных платформ: полная раскладка, 09.10.2026
A3: Листы
A4: Сценарии — сколько стоит продажа одного билета за €10/25/50/100 на ~90 тарифах, включая наши варианты (жёлтые строки). Цены билета можно менять.
A5: Direct merchant — 65 записей: деньги покупателя идут прямо на платёжный счёт организатора (как у Arena), плюс платформы, где организатор может выбрать этот режим.
A6: Собирают на себя — 176 записей: платформа принимает деньги как продавец и выплачивает организатору позже (или режим не выяснен).
A7: Эквайринг — ставки платёжных провайдеров по странам (Stripe, PayPal, Mollie, Flitt, AllPay, местные), чтобы сравнивать полную стоимость.
A8: Курсы — курсы на 09.10.2026, по ним считаются сценарии.
A10: Как собрано
A11: Открытые страницы цен, справочные статьи о сборах, оферты и условия для организаторов; Bright Data + WebFetch; 9 групп по регионам. У каждой цифры есть ссылка (последний столбец).
A12: Уверенность: page — прочитано на странице платформы; snippet — только из выдачи поиска; third_party — из сторонней статьи/обзора. «По запросу» значит, что цена не опубликована — цифр не придумывали.
A13: Ничего не запрашивали у продаж, не регистрировались, форм не заполняли.
A15: Ограничения
... A20: Отчёт с выводами: docs/competitive/pricing_2026-10/report_ru.md

Sheet Сценарии
A1: Сколько стоит продать один билет: сбор платформы + эквайринг, в евро
A2: Жёлтые ячейки P3:S3 — цена билета в евро, можно менять. Ставки (синие) взяты из сырых данных с источниками (листы Direct merchant / Собирают на себя). Эквайринг: если не включён в сбор платформы — стандартная ставка Stripe (или местного провайдера) для внутренних карт этого рынка. Абонентская плата, НДС на сбор и сборы с заказа в сценарий НЕ входят — смотрите «Примечание».
O3: Цена билета, € → | P3: 10 | Q3: 25 | R3: 50 | S3: 100
A4: Модель | B4: Платформа | C4: Рынок | D4: Тариф / вариант | E4: Валюта | F4: Курс за 1 EUR | G4: Сбор, % | H4: Сбор, фикс. (валюта) | I4: Минимум | J4: Потолок | K4: Эквайринг включён | L4: Эквайринг, % | M4: Эквайринг, фикс. | N4: Кто платит по умолчанию | O4: Примечание / уверенность | P4: Всего €, билет €10 | Q4: Всего €, билет €25 | R4: Всего €, билет €50 | S4: Всего €, билет €100 | T4: % от цены, билет €10 | U4: % от цены, билет €25 | V4: % от цены, билет €50 | W4: % от цены, билет €100
A5: Direct merchant | B5: Arena Sold Out | C5: EU | D5: Вариант А: старый сайт, без мест | E5: EUR | F5: =INDEX('Курсы'!$B$4:$B$46,MATCH($E5,'Курсы'!$A$4:$A$46,0)) | G5: 0 | H5: 0.5 | K5: нет | L5: 0.015 | M5: 0.25 | N5: организатор (счёт после сеанса) | O5: Тариф старого сайта, 08_architecture/33 §4.4 | P5: =(MIN(IF($J5="",1E+9,$J5),MAX(IF($I5="",0,$I5),$G5*P$3*$F5+$H5))+IF($K5="да",0,$L5*P$3*$F5+$M5))/$F5 | Q5: =(MIN(IF($J5="",1E+9,$J5),MAX(IF($I5="",0,$I5),$G5*Q$3*$F5+$H5))+IF($K5="да",0,$L5*Q$3*$F5+$M5))/$F5 | R5: =(MIN(IF($J5="",1E+9,$J5),MAX(IF($I5="",0,$I5),$G5*R$3*$F5+$H5))+IF($K5="да",0,$L5*R$3*$F5+$M5))/$F5 | S5: =(MIN(IF($J5="",1E+9,$J5),MAX(IF($I5="",0,$I5),$G5*S$3*$F5+$H5))+IF($K5="да",0,$L5*S$3*$F5+$M5))/$F5 | T5: =P5/P$3 | U5: =Q5/Q$3 | V5: =R5/R$3 | W5: =S5/S$3
A6: Direct merchant | B6: Arena Sold Out | C6: EU | D6: Вариант А: старый сайт, с планом зала | E6: EUR | F6: =INDEX('Курсы'!$B$4:$B$46,MATCH($E6,'Курсы'!$A$4:$A$46,0)) | G6: 0 | H6: 1 | K6: нет | L6: 0.015 | M6: 0.25 | N6: организатор (счёт после сеанса) | O6: Тариф старого сайта | P6: =(MIN(IF($J6="",1E+9,$J6),MAX(IF($I6="",0,$I6),$G6*P$3*$F6+$H6))+IF($K6="да",0,$L6*P$3*$F6+$M6))/$F6 | Q6: =(MIN(IF($J6="",1E+9,$J6),MAX(IF($I6="",0,$I6),$G6*Q$3*$F6+$H6))+IF($K6="да",0,$L6*Q$3*$F6+$M6))/$F6 | R6: =(MIN(IF($J6="",1E+9,$J6),MAX(IF($I6="",0,$I6),$G6*R$3*$F6+$H6))+IF($K6="да",0,$L6*R$3*$F6+$M6))/$F6 | S6: =(MIN(IF($J6="",1E+9,$J6),MAX(IF($I6="",0,$I6),$G6*S$3*$F6+$H6))+IF($K6="да",0,$L6*S$3*$F6+$M6))/$F6 | T6: =P6/P$3 | U6: =Q6/Q$3 | V6: =R6/R$3 | W6: =S6/S$3
A7: Direct merchant | B7: Arena Sold Out | C7: EU | D7: Вариант Б (Марина 08.10): без мест | E7: EUR | F7: =INDEX('Курсы'!$B$4:$B$46,MATCH($E7,'Курсы'!$A$4:$A$46,0)) | G7: 0 | H7: 1 | K7: нет | L7: 0.015 | M7: 0.25 | N7: организатор (счёт после сеанса) | O7: Предложение 08.10, не утверждено | P7: =(MIN(IF($J7="",1E+9,$J7),MAX(IF($I7="",0,$I7),$G7*P$3*$F7+$H7))+IF($K7="да",0,$L7*P$3*$F7+$M7))/$F7 | Q7: =(MIN(IF($J7="",1E+9,$J7),MAX(IF($I7="",0,$I7),$G7*Q$3*$F7+$H7))+IF($K7="да",0,$L7*Q$3*$F7+$M7))/$F7 | R7: =(MIN(IF($J7="",1E+9,$J7),MAX(IF($I7="",0,$I7),$G7*R$3*$F7+$H7))+IF($K7="да",0,$L7*R$3*$F7+$M7))/$F7 | S7: =(MIN(IF($J7="",1E+9,$J7),MAX(IF($I7="",0,$I7),$G7*S$3*$F7+$H7))+IF($K7="да",0,$L7*S$3*$F7+$M7))/$F7 | T7: =P7/P$3 | U7: =Q7/Q$3 | V7: =R7/R$3 | W7: =S7/S$3
A8: Direct merchant | B8: Arena Sold Out | C8: EU | D8: Вариант Б (Марина 08.10): с планом зала | E8: EUR | F8: =INDEX('Курсы'!$B$4:$B$46,MATCH($E8,'Курсы'!$A$4:$A$46,0)) | G8: 0 | H8: 1.5 | K8: нет | L8: 0.015 | M8: 0.25 | N8: организатор (счёт после сеанса) | O8: +0,50 за место, прочтение не подтверждено | P8: =(MIN(IF($J8="",1E+9,$J8),MAX(IF($I8="",0,$I8),$G8*P$3*$F8+$H8))+IF($K8="да",0,$L8*P$3*$F8+$M8))/$F8 | Q8: =(MIN(IF($J8="",1E+9,$J8),MAX(IF($I8="",0,$I8),$G8*Q$3*$F8+$H8))+IF($K8="да",0,$L8*Q$3*$F8+$M8))/$F8 | R8: =(MIN(IF($J8="",1E+9,$J8),MAX(IF($I8="",0,$I8),$G8*R$3*$F8+$H8))+IF($K8="да",0,$L8*R$3*$F8+$M8))/$F8 | S8: =(MIN(IF($J8="",1E+9,$J8),MAX(IF($I8="",0,$I8),$G8*S$3*$F8+$H8))+IF($K8="да",0,$L8*S$3*$F8+$M8))/$F8 | T8: =P8/P$3 | U8: =Q8/Q$3 | V8: =R8/R$3 | W8: =S8/S$3
A9: Direct merchant | B9: Arena Sold Out | C9: EU | D9: Постоянные площадки: 2 % | E9: EUR | F9: =INDEX('Курсы'!$B$4:$B$46,MATCH($E9,'Курсы'!$A$4:$A$46,0)) | G9: 0.02 | H9: 0 | K9: нет | L9: 0.015 | M9: 0.25 | N9: организатор | O9: Тариф старого сайта для площадок | P9: =(MIN(IF($J9="",1E+9,$J9),MAX(IF($I9="",0,$I9),$G9*P$3*$F9+$H9))+IF($K9="да",0,$L9*P$3*$F9+$M9))/$F9 | Q9: =(MIN(IF($J9="",1E+9,$J9),MAX(IF($I9="",0,$I9),$G9*Q$3*$F9+$H9))+IF($K9="да",0,$L9*Q$3*$F9+$M9))/$F9 | R9: =(MIN(IF($J9="",1E+9,$J9),MAX(IF($I9="",0,$I9),$G9*R$3*$F9+$H9))+IF($K9="да",0,$L9*R$3*$F9+$M9))/$F9 | S9: =(MIN(IF($J9="",1E+9,$J9),MAX(IF($I9="",0,$I9),$G9*S$3*$F9+$H9))+IF($K9="да",0,$L9*S$3*$F9+$M9))/$F9 | T9: =P9/P$3 | U9: =Q9/Q$3 | V9: =R9/R$3 | W9: =S9/S$3
A10: Direct merchant | B10: Ticket Tailor | C10: UK | D10: Pay as you sell, без мест | E10: GBP | F10: =INDEX('Курсы'!$B$4:$B$46,MATCH($E10,'Курсы'!$A$4:$A$46,0)) | G10: 0 | H10: 0.6 | K10: нет | L10: 0.015 | M10: 0.2 | N10: настраивается | O10: Цены без НДС (+20 %). Сбор не возвращается при возврате билета | P10: =(MIN(IF($J10="",1E+9,$J10),MAX(IF($I10="",0,$I10),$G10*P$3*$F10+$H10))+IF($K10="да",0,$L10*P$3*$F10+$M10))/$F10 | Q10: =(MIN(IF($J10="",1E+9,$J10),MAX(IF($I10="",0,$I10),$G10*Q$3*$F10+$H10))+IF($K10="да",0,$L10*Q$3*$F10+$M10))/$F10 | R10: =(MIN(IF($J10="",1E+9,$J10),MAX(IF($I10="",0,$I10),$G10*R$3*$F10+$H10))+IF($K10="да",0,$L10*R$3*$F10+$M10))/$F10 | S10: =(MIN(IF($J10="",1E+9,$J10),MAX(IF($I10="",0,$I10),$G10*S$3*$F10+$H10))+IF($K10="да",0,$L10*S$3*$F10+$M10))/$F10 | T10: =P10/P$3 | U10: =Q10/Q$3 | V10: =R10/R$3 | W10: =S10/S$3
A11: Direct merchant | B11: Ticket Tailor | C11: UK | D11: Pay as you sell, с местами (+1 кредит) | E11: GBP | F11: =INDEX('Курсы'!$B$4:$B$46,MATCH($E11,'Курсы'!$A$4:$A$46,0)) | G11: 0 | H11: 1.2 | K11: нет | L11: 0.015 | M11: 0.2 | N11: настраивается | O11: Место с рассадкой = 2 кредита | P11: =(MIN(IF($J11="",1E+9,$J11),MAX(IF($I11="",0,$I11),$G11*P$3*$F11+$H11))+IF($K11="да",0,$L11*P$3*$F11+$M11))/$F11 | Q11: =(MIN(IF($J11="",1E+9,$J11),MAX(IF($I11="",0,$I11),$G11*Q$3*$F11+$H11))+IF($K11="да",0,$L11*Q$3*$F11+$M11))/$F11 | R11: =(MIN(IF($J11="",1E+9,$J11),MAX(IF($I11="",0,$I11),$G11*R$3*$F11+$H11))+IF($K11="да",0,$L11*R$3*$F11+$M11))/$F11 | S11: =(MIN(IF($J11="",1E+9,$J11),MAX(IF($I11="",0,$I11),$G11*S$3*$F11+$H11))+IF($K11="да",0,$L11*S$3*$F11+$M11))/$F11 | T11: =P11/P$3 | U11: =Q11/Q$3 | V11: =R11/R$3 | W11: =S11/S$3
A12: Direct merchant | B12: Ticket Tailor | C12: UK | D12: Предоплата 500 кредитов | E12: GBP | F12: =INDEX('Курсы'!$B$4:$B$46,MATCH($E12,'Курсы'!$A$4:$A$46,0)) | G12: 0 | H12: 0.41 | K12: нет | L12: 0.015 | M12: 0.2 | N12: настраивается | O12: Кредиты не сгорают; крупнейшие пакеты от £0,22 | P12: =(MIN(IF($J12="",1E+9,$J12),MAX(IF($I12="",0,$I12),$G12*P$3*$F12+$H12))+IF($K12="да",0,$L12*P$3*$F12+$M12))/$F12 | Q12: =(MIN(IF($J12="",1E+9,$J12),MAX(IF($I12="",0,$I12),$G12*Q$3*$F12+$H12))+IF($K12="да",0,$L12*Q$3*$F12+$M12))/$F12 | R12: =(MIN(IF($J12="",1E+9,$J12),MAX(IF($I12="",0,$I12),$G12*R$3*$F12+$H12))+IF($K12="да",0,$L12*R$3*$F12+$M12))/$F12 | S12: =(MIN(IF($J12="",1E+9,$J12),MAX(IF($I12="",0,$I12),$G12*S$3*$F12+$H12))+IF($K12="да",0,$L12*S$3*$F12+$M12))/$F12 | T12: =P12/P$3 | U12: =Q12/Q$3 | V12: =R12/R$3 | W12: =S12/S$3
A13: Direct merchant | B13: Ticket Tailor | C13: Еврозона | D13: Pay as you sell, без мест | E13: EUR | F13: =INDEX('Курсы'!$B$4:$B$46,MATCH($E13,'Курсы'!$A$4:$A$46,0)) | G13: 0 | H13: 0.7 | K13: нет | L13: 0.015 | M13: 0.25 | N13: настраивается | O13: Цены без НДС | P13: =(MIN(IF($J13="",1E+9,$J13),MAX(IF($I13="",0,$I13),$G13*P$3*$F13+$H13))+IF($K13="да",0,$L13*P$3*$F13+$M13))/$F13 | Q13: =(MIN(IF($J13="",1E+9,$J13),MAX(IF($I13="",0,$I13),$G13*Q$3*$F13+$H13))+IF($K13="да",0,$L13*Q$3*$F13+$M13))/$F13 | R13: =(MIN(IF($J13="",1E+9,$J13),MAX(IF($I13="",0,$I13),$G13*R$3*$F13+$H13))+IF($K13="да",0,$L13*R$3*$F13+$M13))/$F13 | S13: =(MIN(IF($J13="",1E+9,$J13),MAX(IF($I13="",0,$I13),$G13*S$3*$F13+$H13))+IF($K13="да",0,$L13*S$3*$F13+$M13))/$F13 | T13: =P13/P$3 | U13: =Q13/Q$3 | V13: =R13/R$3 | W13: =S13/S$3
A14: Direct merchant | B14: Ticket Tailor | C14: Еврозона | D14: Предоплата (крупные пакеты, ~) | E14: EUR | F14: =INDEX('Курсы'!$B$4:$B$46,MATCH($E14,'Курсы'!$A$4:$A$46,0)) | G14: 0 | H14: 0.3 | K14: нет | L14: 0.015 | M14: 0.25 | N14: настраивается | O14: «около €0,30»; точная лестница пакетов в EUR не прочитана [snippet] | P14: =(MIN(IF($J14="",1E+9,$J14),MAX(IF($I14="",0,$I14),$G14*P$3*$F14+$H14))+IF($K14="да",0,$L14*P$3*$F14+$M14))/$F14 | Q14: =(MIN(IF($J14="",1E+9,$J14),MAX(IF($I14="",0,$I14),$G14*Q$3*$F14+$H14))+IF($K14="да",0,$L14*Q$3*$F14+$M14))/$F14 | R14: =(MIN(IF($J14="",1E+9,$J14),MAX(IF($I14="",0,$I14),$G14*R$3*$F14+$H14))+IF($K14="да",0,$L14*R$3*$F14+$M14))/$F14 | S14: =(MIN(IF($J14="",1E+9,$J14),MAX(IF($I14="",0,$I14),$G14*S$3*$F14+$H14))+IF($K14="да",0,$L14*S$3*$F14+$M14))/$F14 | T14: =P14/P$3 | U14: =Q14/Q$3 | V14: =R14/R$3 | W14: =S14/S$3
A15: Direct merchant | B15: Ticket Tailor | C15: США | D15: Pay as you sell | E15: USD | F15: =INDEX('Курсы'!$B$4:$B$46,MATCH($E15,'Курсы'!$A$4:$A$46,0)) | G15: 0 | H15: 0.85 | K15: нет | L15: 0.029 | M15: 0.3 | N15: настраивается | P15: =(MIN(IF($J15="",1E+9,$J15),MAX(IF($I15="",0,$I15),$G15*P$3*$F15+$H15))+IF($K15="да",0,$L15*P$3*$F15+$M15))/$F15 | Q15: =(MIN(IF($J15="",1E+9,$J15),MAX(IF($I15="",0,$I15),$G15*Q$3*$F15+$H15))+IF($K15="да",0,$L15*Q$3*$F15+$M15))/$F15 | R15: =(MIN(IF($J15="",1E+9,$J15),MAX(IF($I15="",0,$I15),$G15*R$3*$F15+$H15))+IF($K15="да",0,$L15*R$3*$F15+$M15))/$F15 | S15: =(MIN(IF($J15="",1E+9,$J15),MAX(IF($I15="",0,$I15),$G15*S$3*$F15+$H15))+IF($K15="да",0,$L15*S$3*$F15+$M15))/$F15 | T15: =P15/P$3 | U15: =Q15/Q$3 | V15: =R15/R$3 | W15: =S15/S$3
A16: Direct merchant | B16: Tito | C16: Глобально | D16: Standard | E16: EUR | F16: =INDEX('Курсы'!$B$4:$B$46,MATCH($E16,'Курсы'!$A$4:$A$46,0)) | G16: 0.03 | H16: 0 | J16: 25 | K16: нет | L16: 0.015 | M16: 0.25 | N16: организатор (перекладывать запрещено) | O16: Потолок €25 за билет | P16: =(MIN(IF($J16="",1E+9,$J16),MAX(IF($I16="",0,$I16),$G16*P$3*$F16+$H16))+IF($K16="да",0,$L16*P$3*$F16+$M16))/$F16 | Q16: =(MIN(IF($J16="",1E+9,$J16),MAX(IF($I16="",0,$I16),$G16*Q$3*$F16+$H16))+IF($K16="да",0,$L16*Q$3*$F16+$M16))/$F16 | R16: =(MIN(IF($J16="",1E+9,$J16),MAX(IF($I16="",0,$I16),$G16*R$3*$F16+$H16))+IF($K16="да",0,$L16*R$3*$F16+$M16))/$F16 | S16: =(MIN(IF($J16="",1E+9,$J16),MAX(IF($I16="",0,$I16),$G16*S$3*$F16+$H16))+IF($K16="да",0,$L16*S$3*$F16+$M16))/$F16 | T16: =P16/P$3 | U16: =Q16/Q$3 | V16: =R16/R$3 | W16: =S16/S$3
A17: Direct merchant | B17: pretix (hosted) | C17: Глобально | D17: Pay as you go | E17: EUR | F17: =INDEX('Курсы'!$B$4:$B$46,MATCH($E17,'Курсы'!$A$4:$A$46,0)) | G17: 0.025 | H17: 0 | J17: 15 | K17: нет | L17: 0.015 | M17: 0.25 | N17: организатор | O17: Потолок €15 за билет; некоммерческим 2 % | P17: =(MIN(IF($J17="",1E+9,$J17),MAX(IF($I17="",0,$I17),$G17*P$3*$F17+$H17))+IF($K17="да",0,$L17*P$3*$F17+$M17))/$F17 | Q17: =(MIN(IF($J17="",1E+9,$J17),MAX(IF($I17="",0,$I17),$G17*Q$3*$F17+$H17))+IF($K17="да",0,$L17*Q$3*$F17+$M17))/$F17 | R17: =(MIN(IF($J17="",1E+9,$J17),MAX(IF($I17="",0,$I17),$G17*R$3*$F17+$H17))+IF($K17="да",0,$L17*R$3*$F17+$M17))/$F17 | S17: =(MIN(IF($J17="",1E+9,$J17),MAX(IF($I17="",0,$I17),$G17*S$3*$F17+$H17))+IF($K17="да",0,$L17*S$3*$F17+$M17))/$F17 | T17: =P17/P$3 | U17: =Q17/Q$3 | V17: =R17/R$3 | W17: =S17/S$3
A18: Оба (показан direct) | B18: Humanitix | C18: Еврозона | D18: Standard (свой Stripe) | E18: EUR | F18: =INDEX('Курсы'!$B$4:$B$46,MATCH($E18,'Курсы'!$A$4:$A$46,0)) | G18: 0.021 | H18: 0.99 | K18: нет | L18: 0.015 | M18: 0.25 | N18: покупатель по умолчанию | O18: Прибыль идёт на благотворительность | P18: =(MIN(IF($J18="",1E+9,$J18),MAX(IF($I18="",0,$I18),$G18*P$3*$F18+$H18))+IF($K18="да",0,$L18*P$3*$F18+$M18))/$F18 | Q18: =(MIN(IF($J18="",1E+9,$J18),MAX(IF($I18="",0,$I18),$G18*Q$3*$F18+$H18))+IF($K18="да",0,$L18*Q$3*$F18+$M18))/$F18 | R18: =(MIN(IF($J18="",1E+9,$J18),MAX(IF($I18="",0,$I18),$G18*R$3*$F18+$H18))+IF($K18="да",0,$L18*R$3*$F18+$M18))/$F18 | S18: =(MIN(IF($J18="",1E+9,$J18),MAX(IF($I18="",0,$I18),$G18*S$3*$F18+$H18))+IF($K18="да",0,$L18*S$3*$F18+$M18))/$F18 | T18: =P18/P$3 | U18: =Q18/Q$3 | V18: =R18/R$3 | W18: =S18/S$3
A19: Direct merchant | B19: Luma | C19: Глобально | D19: Free | E19: USD | F19: =INDEX('Курсы'!$B$4:$B$46,MATCH($E19,'Курсы'!$A$4:$A$46,0)) | G19: 0.05 | H19: 0 | K19: нет | L19: 0.029 | M19: 0.3 | N19: организатор | O19: Luma Plus $69/мес = 0 % | P19: =(MIN(IF($J19="",1E+9,$J19),MAX(IF($I19="",0,$I19),$G19*P$3*$F19+$H19))+IF($K19="да",0,$L19*P$3*$F19+$M19))/$F19 | Q19: =(MIN(IF($J19="",1E+9,$J19),MAX(IF($I19="",0,$I19),$G19*Q$3*$F19+$H19))+IF($K19="да",0,$L19*Q$3*$F19+$M19))/$F19 | R19: =(MIN(IF($J19="",1E+9,$J19),MAX(IF($I19="",0,$I19),$G19*R$3*$F19+$H19))+IF($K19="да",0,$L19*R$3*$F19+$M19))/$F19 | S19: =(MIN(IF($J19="",1E+9,$J19),MAX(IF($I19="",0,$I19),$G19*S$3*$F19+$H19))+IF($K19="да",0,$L19*S$3*$F19+$M19))/$F19 | T19: =P19/P$3 | U19: =Q19/Q$3 | V19: =R19/R$3 | W19: =S19/S$3
A20: Оба (показан direct) | B20: TryBooking | C20: UK | D20: You handle payments (свой Stripe) | E20: GBP | F20: =INDEX('Курсы'!$B$4:$B$46,MATCH($E20,'Курсы'!$A$4:$A$46,0)) | G20: 0 | H20: 0.75 | K20: нет | L20: 0.015 | M20: 0.2 | N20: настраивается | O20: Платформа «никогда не держит» деньги | P20: =(MIN(IF($J20="",1E+9,$J20),MAX(IF($I20="",0,$I20),$G20*P$3*$F20+$H20))+IF($K20="да",0,$L20*P$3*$F20+$M20))/$F20 | Q20: =(MIN(IF($J20="",1E+9,$J20),MAX(IF($I20="",0,$I20),$G20*Q$3*$F20+$H20))+IF($K20="да",0,$L20*Q$3*$F20+$M20))/$F20 | R20: =(MIN(IF($J20="",1E+9,$J20),MAX(IF($I20="",0,$I20),$G20*R$3*$F20+$H20))+IF($K20="да",0,$L20*R$3*$F20+$M20))/$F20 | S20: =(MIN(IF($J20="",1E+9,$J20),MAX(IF($I20="",0,$I20),$G20*S$3*$F20+$H20))+IF($K20="да",0,$L20*S$3*$F20+$M20))/$F20 | T20: =P20/P$3 | U20: =Q20/Q$3 | V20: =R20/R$3 | W20: =S20/S$3
A21: Оба (показан direct) | B21: TryBooking | C21: Австралия | D21: Own Stripe account | E21: AUD | F21: =INDEX('Курсы'!$B$4:$B$46,MATCH($E21,'Курсы'!$A$4:$A$46,0)) | G21: 0.01 | H21: 0.5 | K21: нет | L21: 0.0165 | M21: 0.3 | N21: настраивается | P21: =(MIN(IF($J21="",1E+9,$J21),MAX(IF($I21="",0,$I21),$G21*P$3*$F21+$H21))+IF($K21="да",0,$L21*P$3*$F21+$M21))/$F21 | Q21: =(MIN(IF($J21="",1E+9,$J21),MAX(IF($I21="",0,$I21),$G21*Q$3*$F21+$H21))+IF($K21="да",0,$L21*Q$3*$F21+$M21))/$F21 | R21: =(MIN(IF($J21="",1E+9,$J21),MAX(IF($I21="",0,$I21),$G21*R$3*$F21+$H21))+IF($K21="да",0,$L21*R$3*$F21+$M21))/$F21 | S21: =(MIN(IF($J21="",1E+9,$J21),MAX(IF($I21="",0,$I21),$G21*S$3*$F21+$H21))+IF($K21="да",0,$L21*S$3*$F21+$M21))/$F21 | T21: =P21/P$3 | U21: =Q21/Q$3 | V21: =R21/R$3 | W21: =S21/S$3
A22: Оба (показан direct) | B22: TicketSource | C22: UK | D22: Свой Stripe | E22: GBP | F22: =INDEX('Курсы'!$B$4:$B$46,MATCH($E22,'Курсы'!$A$4:$A$46,0)) | G22: 0.045 | H22: 0 | K22: нет | L22: 0.015 | M22: 0.2 | N22: настраивается | O22: С заказа, а не с билета; +НДС | P22: =(MIN(IF($J22="",1E+9,$J22),MAX(IF($I22="",0,$I22),$G22*P$3*$F22+$H22))+IF($K22="да",0,$L22*P$3*$F22+$M22))/$F22 | Q22: =(MIN(IF($J22="",1E+9,$J22),MAX(IF($I22="",0,$I22),$G22*Q$3*$F22+$H22))+IF($K22="да",0,$L22*Q$3*$F22+$M22))/$F22 | R22: =(MIN(IF($J22="",1E+9,$J22),MAX(IF($I22="",0,$I22),$G22*R$3*$F22+$H22))+IF($K22="да",0,$L22*R$3*$F22+$M22))/$F22 | S22: =(MIN(IF($J22="",1E+9,$J22),MAX(IF($I22="",0,$I22),$G22*S$3*$F22+$H22))+IF($K22="да",0,$L22*S$3*$F22+$M22))/$F22 | T22: =P22/P$3 | U22: =Q22/Q$3 | V22: =R22/R$3 | W22: =S22/S$3
A23: Direct merchant | B23: SimpleTix | C23: Глобально | D23: Online | E23: USD | F23: =INDEX('Курсы'!$B$4:$B$46,MATCH($E23,'Курсы'!$A$4:$A$46,0)) | G23: 0.02 | H23: 0.79 | J23: 9.99 | K23: нет | L23: 0.029 | M23: 0.3 | N23: настраивается | O23: Удерживает внутри платежа Stripe/PayPal/Square | P23: =(MIN(IF($J23="",1E+9,$J23),MAX(IF($I23="",0,$I23),$G23*P$3*$F23+$H23))+IF($K23="да",0,$L23*P$3*$F23+$M23))/$F23 | Q23: =(MIN(IF($J23="",1E+9,$J23),MAX(IF($I23="",0,$I23),$G23*Q$3*$F23+$H23))+IF($K23="да",0,$L23*Q$3*$F23+$M23))/$F23 | R23: =(MIN(IF($J23="",1E+9,$J23),MAX(IF($I23="",0,$I23),$G23*R$3*$F23+$H23))+IF($K23="да",0,$L23*R$3*$F23+$M23))/$F23 | S23: =(MIN(IF($J23="",1E+9,$J23),MAX(IF($I23="",0,$I23),$G23*S$3*$F23+$H23))+IF($K23="да",0,$L23*S$3*$F23+$M23))/$F23 | T23: =P23/P$3 | U23: =Q23/Q$3 | V23: =R23/R$3 | W23: =S23/S$3
A24: Direct merchant | B24: Yapsody | C24: Глобально | D24: General seating | E24: USD | F24: =INDEX('Курсы'!$B$4:$B$46,MATCH($E24,'Курсы'!$A$4:$A$46,0)) | G24: 0.0175 | H24: 0.59 | K24: нет | L24: 0.029 | M24: 0.3 | N24: настраивается | O24: Счёт раз в месяц | P24: =(MIN(IF($J24="",1E+9,$J24),MAX(IF($I24="",0,$I24),$G24*P$3*$F24+$H24))+IF($K24="да",0,$L24*P$3*$F24+$M24))/$F24 | Q24: =(MIN(IF($J24="",1E+9,$J24),MAX(IF($I24="",0,$I24),$G24*Q$3*$F24+$H24))+IF($K24="да",0,$L24*Q$3*$F24+$M24))/$F24 | R24: =(MIN(IF($J24="",1E+9,$J24),MAX(IF($I24="",0,$I24),$G24*R$3*$F24+$H24))+IF($K24="да",0,$L24*R$3*$F24+$M24))/$F24 | S24: =(MIN(IF($J24="",1E+9,$J24),MAX(IF($I24="",0,$I24),$G24*S$3*$F24+$H24))+IF($K24="да",0,$L24*S$3*$F24+$M24))/$F24 | T24: =P24/P$3 | U24: =Q24/Q$3 | V24: =R24/R$3 | W24: =S24/S$3
A25: Direct merchant | B25: Yapsody | C25: Глобально | D25: Reserved seating | E25: USD | F25: =INDEX('Курсы'!$B$4:$B$46,MATCH($E25,'Курсы'!$A$4:$A$46,0)) | G25: 0.0249 | H25: 0.98 | K25: нет | L25: 0.029 | M25: 0.3 | N25: настраивается | P25: =(MIN(IF($J25="",1E+9,$J25),MAX(IF($I25="",0,$I25),$G25*P$3*$F25+$H25))+IF($K25="да",0,$L25*P$3*$F25+$M25))/$F25 | Q25: =(MIN(IF($J25="",1E+9,$J25),MAX(IF($I25="",0,$I25),$G25*Q$3*$F25+$H25))+IF($K25="да",0,$L25*Q$3*$F25+$M25))/$F25 | R25: =(MIN(IF($J25="",1E+9,$J25),MAX(IF($I25="",0,$I25),$G25*R$3*$F25+$H25))+IF($K25="да",0,$L25*R$3*$F25+$M25))/$F25 | S25: =(MIN(IF($J25="",1E+9,$J25),MAX(IF($I25="",0,$I25),$G25*S$3*$F25+$H25))+IF($K25="да",0,$L25*S$3*$F25+$M25))/$F25 | T25: =P25/P$3 | U25: =Q25/Q$3 | V25: =R25/R$3 | W25: =S25/S$3
A26: Direct merchant | B26: ThunderTix | C26: США | D26: General Admission | E26: USD | F26: =INDEX('Курсы'!$B$4:$B$46,MATCH($E26,'Курсы'!$A$4:$A$46,0)) | G26: 0 | H26: 1 | K26: нет | L26: 0.029 | M26: 0.3 | N26: — | O26: Плюс $20/мес (не учтено в сценарии) | P26: =(MIN(IF($J26="",1E+9,$J26),MAX(IF($I26="",0,$I26),$G26*P$3*$F26+$H26))+IF($K26="да",0,$L26*P$3*$F26+$M26))/$F26 | Q26: =(MIN(IF($J26="",1E+9,$J26),MAX(IF($I26="",0,$I26),$G26*Q$3*$F26+$H26))+IF($K26="да",0,$L26*Q$3*$F26+$M26))/$F26 | R26: =(MIN(IF($J26="",1E+9,$J26),MAX(IF($I26="",0,$I26),$G26*R$3*$F26+$H26))+IF($K26="да",0,$L26*R$3*$F26+$M26))/$F26 | S26: =(MIN(IF($J26="",1E+9,$J26),MAX(IF($I26="",0,$I26),$G26*S$3*$F26+$H26))+IF($K26="да",0,$L26*S$3*$F26+$M26))/$F26 | T26: =P26/P$3 | U26: =Q26/Q$3 | V26: =R26/R$3 | W26: =S26/S$3
A27: Direct merchant | B27: ThunderTix | C27: США | D27: Reserved Seating | E27: USD | F27: =INDEX('Курсы'!$B$4:$B$46,MATCH($E27,'Курсы'!$A$4:$A$46,0)) | G27: 0 | H27: 1.25 | K27: нет | L27: 0.029 | M27: 0.3 | N27: — | O27: Плюс $25/мес; схема $0,55 за место, мин. $250 | P27: =(MIN(IF($J27="",1E+9,$J27),MAX(IF($I27="",0,$I27),$G27*P$3*$F27+$H27))+IF($K27="да",0,$L27*P$3*$F27+$M27))/$F27 | Q27: =(MIN(IF($J27="",1E+9,$J27),MAX(IF($I27="",0,$I27),$G27*Q$3*$F27+$H27))+IF($K27="да",0,$L27*Q$3*$F27+$M27))/$F27 | R27: =(MIN(IF($J27="",1E+9,$J27),MAX(IF($I27="",0,$I27),$G27*R$3*$F27+$H27))+IF($K27="да",0,$L27*R$3*$F27+$M27))/$F27 | S27: =(MIN(IF($J27="",1E+9,$J27),MAX(IF($I27="",0,$I27),$G27*S$3*$F27+$H27))+IF($K27="да",0,$L27*S$3*$F27+$M27))/$F27 | T27: =P27/P$3 | U27: =Q27/Q$3 | V27: =R27/R$3 | W27: =S27/S$3
A28: Direct merchant | B28: Brushfire | C28: США | D28: Other events | E28: USD | F28: =INDEX('Курсы'!$B$4:$B$46,MATCH($E28,'Курсы'!$A$4:$A$46,0)) | G28: 0.01 | H28: 1.5 | K28: нет | L28: 0.029 | M28: 0.3 | N28: настраивается | P28: =(MIN(IF($J28="",1E+9,$J28),MAX(IF($I28="",0,$I28),$G28*P$3*$F28+$H28))+IF($K28="да",0,$L28*P$3*$F28+$M28))/$F28 | Q28: =(MIN(IF($J28="",1E+9,$J28),MAX(IF($I28="",0,$I28),$G28*Q$3*$F28+$H28))+IF($K28="да",0,$L28*Q$3*$F28+$M28))/$F28 | R28: =(MIN(IF($J28="",1E+9,$J28),MAX(IF($I28="",0,$I28),$G28*R$3*$F28+$H28))+IF($K28="да",0,$L28*R$3*$F28+$M28))/$F28 | S28: =(MIN(IF($J28="",1E+9,$J28),MAX(IF($I28="",0,$I28),$G28*S$3*$F28+$H28))+IF($K28="да",0,$L28*S$3*$F28+$M28))/$F28 | T28: =P28/P$3 | U28: =Q28/Q$3 | V28: =R28/R$3 | W28: =S28/S$3
A29: Direct merchant | B29: Ticketbud | C29: США | D29: Paid events | E29: USD | F29: =INDEX('Курсы'!$B$4:$B$46,MATCH($E29,'Курсы'!$A$4:$A$46,0)) | G29: 0.02 | H29: 0.99 | K29: нет | L29: 0.029 | M29: 0.3 | N29: покупатель | P29: =(MIN(IF($J29="",1E+9,$J29),MAX(IF($I29="",0,$I29),$G29*P$3*$F29+$H29))+IF($K29="да",0,$L29*P$3*$F29+$M29))/$F29 | Q29: =(MIN(IF($J29="",1E+9,$J29),MAX(IF($I29="",0,$I29),$G29*Q$3*$F29+$H29))+IF($K29="да",0,$L29*Q$3*$F29+$M29))/$F29 | R29: =(MIN(IF($J29="",1E+9,$J29),MAX(IF($I29="",0,$I29),$G29*R$3*$F29+$H29))+IF($K29="да",0,$L29*R$3*$F29+$M29))/$F29 | S29: =(MIN(IF($J29="",1E+9,$J29),MAX(IF($I29="",0,$I29),$G29*S$3*$F29+$H29))+IF($K29="да",0,$L29*S$3*$F29+$M29))/$F29 | T29: =P29/P$3 | U29: =Q29/Q$3 | V29: =R29/R$3 | W29: =S29/S$3
A30: Direct merchant | B30: BZUCO | C30: Чехия | D30: Základní (предоплаченный кредит) | E30: CZK | F30: =INDEX('Курсы'!$B$4:$B$46,MATCH($E30,'Курсы'!$A$4:$A$46,0)) | G30: 0.02 | H30: 0 | K30: нет | L30: 0.015 | M30: 6.5 | N30: настраивается | O30: Мин. годовой кредит 10–50 тыс. CZK | P30: =(MIN(IF($J30="",1E+9,$J30),MAX(IF($I30="",0,$I30),$G30*P$3*$F30+$H30))+IF($K30="да",0,$L30*P$3*$F30+$M30))/$F30 | Q30: =(MIN(IF($J30="",1E+9,$J30),MAX(IF($I30="",0,$I30),$G30*Q$3*$F30+$H30))+IF($K30="да",0,$L30*Q$3*$F30+$M30))/$F30 | R30: =(MIN(IF($J30="",1E+9,$J30),MAX(IF($I30="",0,$I30),$G30*R$3*$F30+$H30))+IF($K30="да",0,$L30*R$3*$F30+$M30))/$F30 | S30: =(MIN(IF($J30="",1E+9,$J30),MAX(IF($I30="",0,$I30),$G30*S$3*$F30+$H30))+IF($K30="да",0,$L30*S$3*$F30+$M30))/$F30 | T30: =P30/P$3 | U30: =Q30/Q$3 | V30: =R30/R$3 | W30: =S30/S$3
A31: Direct merchant | B31: Paysera Tickets | C31: Прибалтика | D31: Platform fee + Paysera Checkout | E31: EUR | F31: =INDEX('Курсы'!$B$4:$B$46,MATCH($E31,'Курсы'!$A$4:$A$46,0)) | G31: 0.02 | H31: 0 | I31: 0.15 | J31: 1 | K31: нет | L31: 0.009 | M31: 0.1 | N31: — | O31: Эквайринг Paysera 0,9 % (мин 0,10, макс 0,40) — потолок эквайринга в сценарии не учтён | P31: =(MIN(IF($J31="",1E+9,$J31),MAX(IF($I31="",0,$I31),$G31*P$3*$F31+$H31))+IF($K31="да",0,$L31*P$3*$F31+$M31))/$F31 | Q31: =(MIN(IF($J31="",1E+9,$J31),MAX(IF($I31="",0,$I31),$G31*Q$3*$F31+$H31))+IF($K31="да",0,$L31*Q$3*$F31+$M31))/$F31 | R31: =(MIN(IF($J31="",1E+9,$J31),MAX(IF($I31="",0,$I31),$G31*R$3*$F31+$H31))+IF($K31="да",0,$L31*R$3*$F31+$M31))/$F31 | S31: =(MIN(IF($J31="",1E+9,$J31),MAX(IF($I31="",0,$I31),$G31*S$3*$F31+$H31))+IF($K31="да",0,$L31*S$3*$F31+$M31))/$F31 | T31: =P31/P$3 | U31: =Q31/Q$3 | V31: =R31/R$3 | W31: =S31/S$3
A32: Direct merchant | B32: Shownet | C32: Литва | D32: System commission | E32: EUR | F32: =INDEX('Курсы'!$B$4:$B$46,MATCH($E32,'Курсы'!$A$4:$A$46,0)) | G32: 0.025 | H32: 0 | I32: 0.06 | K32: нет | L32: 0.015 | M32: 0.25 | N32: — | P32: =(MIN(IF($J32="",1E+9,$J32),MAX(IF($I32="",0,$I32),$G32*P$3*$F32+$H32))+IF($K32="да",0,$L32*P$3*$F32+$M32))/$F32 | Q32: =(MIN(IF($J32="",1E+9,$J32),MAX(IF($I32="",0,$I32),$G32*Q$3*$F32+$H32))+IF($K32="да",0,$L32*Q$3*$F32+$M32))/$F32 | R32: =(MIN(IF($J32="",1E+9,$J32),MAX(IF($I32="",0,$I32),$G32*R$3*$F32+$H32))+IF($K32="да",0,$L32*R$3*$F32+$M32))/$F32 | S32: =(MIN(IF($J32="",1E+9,$J32),MAX(IF($I32="",0,$I32),$G32*S$3*$F32+$H32))+IF($K32="да",0,$L32*S$3*$F32+$M32))/$F32 | T32: =P32/P$3 | U32: =Q32/Q$3 | V32: =R32/R$3 | W32: =S32/S$3
A33: Direct merchant | B33: eTichet.ro | C33: Румыния | D33: Standard | E33: RON | F33: =INDEX('Курсы'!$B$4:$B$46,MATCH($E33,'Курсы'!$A$4:$A$46,0)) | G33: 0.05 | H33: 0 | K33: нет | L33: 0.015 | M33: 1.34 | N33: организатор | P33: =(MIN(IF($J33="",1E+9,$J33),MAX(IF($I33="",0,$I33),$G33*P$3*$F33+$H33))+IF($K33="да",0,$L33*P$3*$F33+$M33))/$F33 | Q33: =(MIN(IF($J33="",1E+9,$J33),MAX(IF($I33="",0,$I33),$G33*Q$3*$F33+$H33))+IF($K33="да",0,$L33*Q$3*$F33+$M33))/$F33 | R33: =(MIN(IF($J33="",1E+9,$J33),MAX(IF($I33="",0,$I33),$G33*R$3*$F33+$H33))+IF($K33="да",0,$L33*R$3*$F33+$M33))/$F33 | S33: =(MIN(IF($J33="",1E+9,$J33),MAX(IF($I33="",0,$I33),$G33*S$3*$F33+$H33))+IF($K33="да",0,$L33*S$3*$F33+$M33))/$F33 | T33: =P33/P$3 | U33: =Q33/Q$3 | V33: =R33/R$3 | W33: =S33/S$3
A34: Direct merchant | B34: RegToEvent | C34: Украина / межд. | D34: Small events | E34: EUR | F34: =INDEX('Курсы'!$B$4:$B$46,MATCH($E34,'Курсы'!$A$4:$A$46,0)) | G34: 0.029 | H34: 0.39 | K34: нет | L34: 0.015 | M34: 0.25 | N34: настраивается | P34: =(MIN(IF($J34="",1E+9,$J34),MAX(IF($I34="",0,$I34),$G34*P$3*$F34+$H34))+IF($K34="да",0,$L34*P$3*$F34+$M34))/$F34 | Q34: =(MIN(IF($J34="",1E+9,$J34),MAX(IF($I34="",0,$I34),$G34*Q$3*$F34+$H34))+IF($K34="да",0,$L34*Q$3*$F34+$M34))/$F34 | R34: =(MIN(IF($J34="",1E+9,$J34),MAX(IF($I34="",0,$I34),$G34*R$3*$F34+$H34))+IF($K34="да",0,$L34*R$3*$F34+$M34))/$F34 | S34: =(MIN(IF($J34="",1E+9,$J34),MAX(IF($I34="",0,$I34),$G34*S$3*$F34+$H34))+IF($K34="да",0,$L34*S$3*$F34+$M34))/$F34 | T34: =P34/P$3 | U34: =Q34/Q$3 | V34: =R34/R$3 | W34: =S34/S$3
A35: Direct merchant | B35: RegToEvent | C35: Украина / межд. | D35: С местами (нижняя ставка) | E35: EUR | F35: =INDEX('Курсы'!$B$4:$B$46,MATCH($E35,'Курсы'!$A$4:$A$46,0)) | G35: 0.045 | H35: 0.3 | K35: нет | L35: 0.015 | M35: 0.25 | N35: настраивается | P35: =(MIN(IF($J35="",1E+9,$J35),MAX(IF($I35="",0,$I35),$G35*P$3*$F35+$H35))+IF($K35="да",0,$L35*P$3*$F35+$M35))/$F35 | Q35: =(MIN(IF($J35="",1E+9,$J35),MAX(IF($I35="",0,$I35),$G35*Q$3*$F35+$H35))+IF($K35="да",0,$L35*Q$3*$F35+$M35))/$F35 | R35: =(MIN(IF($J35="",1E+9,$J35),MAX(IF($I35="",0,$I35),$G35*R$3*$F35+$H35))+IF($K35="да",0,$L35*R$3*$F35+$M35))/$F35 | S35: =(MIN(IF($J35="",1E+9,$J35),MAX(IF($I35="",0,$I35),$G35*S$3*$F35+$H35))+IF($K35="да",0,$L35*S$3*$F35+$M35))/$F35 | T35: =P35/P$3 | U35: =Q35/Q$3 | V35: =R35/R$3 | W35: =S35/S$3
A36: Direct merchant | B36: Event.net.ua | C36: Украина | D36: Без мест | E36: UAH | F36: =INDEX('Курсы'!$B$4:$B$46,MATCH($E36,'Курсы'!$A$4:$A$46,0)) | G36: 0 | H36: 8 | K36: нет | L36: 0.013 | M36: 0 | N36: организатор | O36: Эквайринг monobank 1,3 % | P36: =(MIN(IF($J36="",1E+9,$J36),MAX(IF($I36="",0,$I36),$G36*P$3*$F36+$H36))+IF($K36="да",0,$L36*P$3*$F36+$M36))/$F36 | Q36: =(MIN(IF($J36="",1E+9,$J36),MAX(IF($I36="",0,$I36),$G36*Q$3*$F36+$H36))+IF($K36="да",0,$L36*Q$3*$F36+$M36))/$F36 | R36: =(MIN(IF($J36="",1E+9,$J36),MAX(IF($I36="",0,$I36),$G36*R$3*$F36+$H36))+IF($K36="да",0,$L36*R$3*$F36+$M36))/$F36 | S36: =(MIN(IF($J36="",1E+9,$J36),MAX(IF($I36="",0,$I36),$G36*S$3*$F36+$H36))+IF($K36="да",0,$L36*S$3*$F36+$M36))/$F36 | T36: =P36/P$3 | U36: =Q36/Q$3 | V36: =R36/R$3 | W36: =S36/S$3
A37: Direct merchant | B37: Tikzet | C37: Бразилия | D37: Предоплата 300 билетов | E37: BRL | F37: =INDEX('Курсы'!$B$4:$B$46,MATCH($E37,'Курсы'!$A$4:$A$46,0)) | G37: 0 | H37: 1.4 | K37: нет | L37: 0.0498 | M37: 0 | N37: организатор | O37: Эквайринг Mercado Pago BR 4,98 % (мгновенный) | P37: =(MIN(IF($J37="",1E+9,$J37),MAX(IF($I37="",0,$I37),$G37*P$3*$F37+$H37))+IF($K37="да",0,$L37*P$3*$F37+$M37))/$F37 | Q37: =(MIN(IF($J37="",1E+9,$J37),MAX(IF($I37="",0,$I37),$G37*Q$3*$F37+$H37))+IF($K37="да",0,$L37*Q$3*$F37+$M37))/$F37 | R37: =(MIN(IF($J37="",1E+9,$J37),MAX(IF($I37="",0,$I37),$G37*R$3*$F37+$H37))+IF($K37="да",0,$L37*R$3*$F37+$M37))/$F37 | S37: =(MIN(IF($J37="",1E+9,$J37),MAX(IF($I37="",0,$I37),$G37*S$3*$F37+$H37))+IF($K37="да",0,$L37*S$3*$F37+$M37))/$F37 | T37: =P37/P$3 | U37: =Q37/Q$3 | V37: =R37/R$3 | W37: =S37/S$3
A38: Direct merchant | B38: Tikzet | C38: Мексика | D38: Предоплата 300 билетов | E38: MXN | F38: =INDEX('Курсы'!$B$4:$B$46,MATCH($E38,'Курсы'!$A$4:$A$46,0)) | G38: 0 | H38: 4.8 | K38: нет | L38: 0.0405 | M38: 0 | N38: организатор | O38: Mercado Pago MX 3,49 % + IVA | P38: =(MIN(IF($J38="",1E+9,$J38),MAX(IF($I38="",0,$I38),$G38*P$3*$F38+$H38))+IF($K38="да",0,$L38*P$3*$F38+$M38))/$F38 | Q38: =(MIN(IF($J38="",1E+9,$J38),MAX(IF($I38="",0,$I38),$G38*Q$3*$F38+$H38))+IF($K38="да",0,$L38*Q$3*$F38+$M38))/$F38 | R38: =(MIN(IF($J38="",1E+9,$J38),MAX(IF($I38="",0,$I38),$G38*R$3*$F38+$H38))+IF($K38="да",0,$L38*R$3*$F38+$M38))/$F38 | S38: =(MIN(IF($J38="",1E+9,$J38),MAX(IF($I38="",0,$I38),$G38*S$3*$F38+$H38))+IF($K38="да",0,$L38*S$3*$F38+$M38))/$F38 | T38: =P38/P$3 | U38: =Q38/Q$3 | V38: =R38/R$3 | W38: =S38/S$3
A39: Direct merchant | B39: Enter.ar | C39: Аргентина | D39: Standard | E39: ARS | F39: =INDEX('Курсы'!$B$4:$B$46,MATCH($E39,'Курсы'!$A$4:$A$46,0)) | G39: 0.02 | H39: 0 | K39: нет | L39: 0.073 | M39: 0 | N39: организатор | O39: Mercado Pago AR ~6,29 % + IVA (мгновенно), неточно | P39: =(MIN(IF($J39="",1E+9,$J39),MAX(IF($I39="",0,$I39),$G39*P$3*$F39+$H39))+IF($K39="да",0,$L39*P$3*$F39+$M39))/$F39 | Q39: =(MIN(IF($J39="",1E+9,$J39),MAX(IF($I39="",0,$I39),$G39*Q$3*$F39+$H39))+IF($K39="да",0,$L39*Q$3*$F39+$M39))/$F39 | R39: =(MIN(IF($J39="",1E+9,$J39),MAX(IF($I39="",0,$I39),$G39*R$3*$F39+$H39))+IF($K39="да",0,$L39*R$3*$F39+$M39))/$F39 | S39: =(MIN(IF($J39="",1E+9,$J39),MAX(IF($I39="",0,$I39),$G39*S$3*$F39+$H39))+IF($K39="да",0,$L39*S$3*$F39+$M39))/$F39 | T39: =P39/P$3 | U39: =Q39/Q$3 | V39: =R39/R$3 | W39: =S39/S$3
A40: Direct merchant | B40: MaunaOne | C40: Мексика | D40: Inicia (бесплатный) | E40: MXN | F40: =INDEX('Курсы'!$B$4:$B$46,MATCH($E40,'Курсы'!$A$4:$A$46,0)) | G40: 0.05 | H40: 0 | K40: нет | L40: 0.042 | M40: 3.48 | N40: настраивается | O40: Stripe MX 3,6 % + 3 MXN + IVA | P40: =(MIN(IF($J40="",1E+9,$J40),MAX(IF($I40="",0,$I40),$G40*P$3*$F40+$H40))+IF($K40="да",0,$L40*P$3*$F40+$M40))/$F40 | Q40: =(MIN(IF($J40="",1E+9,$J40),MAX(IF($I40="",0,$I40),$G40*Q$3*$F40+$H40))+IF($K40="да",0,$L40*Q$3*$F40+$M40))/$F40 | R40: =(MIN(IF($J40="",1E+9,$J40),MAX(IF($I40="",0,$I40),$G40*R$3*$F40+$H40))+IF($K40="да",0,$L40*R$3*$F40+$M40))/$F40 | S40: =(MIN(IF($J40="",1E+9,$J40),MAX(IF($I40="",0,$I40),$G40*S$3*$F40+$H40))+IF($K40="да",0,$L40*S$3*$F40+$M40))/$F40 | T40: =P40/P$3 | U40: =Q40/Q$3 | V40: =R40/R$3 | W40: =S40/S$3
...

Sheet Курсы
A1: Курсы валют: единиц валюты за 1 EUR, 09.10.2026
A3: Валюта | B3: За 1 EUR | C3: Источник
A4: EUR | B4: 1 | C4: ECB reference rate 09.10.2026 (api.frankfurter.dev)
A5: AUD | B5: 1.6052 | C5: ECB reference rate 09.10.2026 (api.frankfurter.dev)
A6: BRL | B6: 5.6086 | C6: ECB reference rate 09.10.2026 (api.frankfurter.dev)
A7: CAD | B7: 1.5942 | C7: ECB reference rate 09.10.2026 (api.frankfurter.dev)
A8: CHF | B8: 0.9313 | C8: ECB reference rate 09.10.2026 (api.frankfurter.dev)
A9: CZK | B9: 24.369 | C9: ECB reference rate 09.10.2026 (api.frankfurter.dev)
A10: DKK | B10: 7.4751 | C10: ECB reference rate 09.10.2026 (api.frankfurter.dev)
A11: GBP | B11: 0.84763 | C11: ECB reference rate 09.10.2026 (api.frankfurter.dev)
A12: HKD | B12: 8.794 | C12: ECB reference rate 09.10.2026 (api.frankfurter.dev)
A13: HUF | B13: 365.08 | C13: ECB reference rate 09.10.2026 (api.frankfurter.dev)
A14: IDR | B14: 20036.94 | C14: ECB reference rate 09.10.2026 (api.frankfurter.dev)
A15: ILS | B15: 3.426 | C15: ECB reference rate 09.10.2026 (api.frankfurter.dev)
... A46: TWD | B46: 35.782058 | C46: open.er-api.com, обновлено 09.10.2026 00:02 UTC (ECB эту валюту не публикует)

Sheet Direct merchant
A1: Регион | B1: Платформа | C1: Сайт | D1: Рынок | E1: Валюта | F1: Движение денег | G1: Как берёт деньги / выплаты | H1: Модель | I1: Тарифы и сбор за билет | J1: Предоплата | K1: Эквайринг | L1: Кто платит | M1: Бесплатные билеты | N1: Рассадка | O1: Выплаты | P1: Возвраты и чарджбэки | Q1: НДС | R1: Мелкий шрифт (звёздочки) | S1: Доп. услуги | T1: Enterprise / по запросу | U1: Сегмент | V1: Уверенность | W1: Источники
A2: Глобальные self-serve | B2: Ticket Tailor | C2: https://www.tickettailor.com | D2: UK | E2: GBP | F2: direct merchant | G2: Direct merchant: buyer pays straight into the organizer's own Stripe/PayPal/Square account (revenue appears almost immediately, bank transfer takes about a week); TT never holds the money. TT fee collection: Pre-pay = card charged immediately when credits are bought (optional auto top-up monthly or when <=25 credits left). PAYG on Stripe = fee deducted automatically at the point of sale; PAYG on PayPal/Square/offline = TT charges the organizer's card on file monthly, or every 50 usage units, or 2 days after the last event ends. | H2: flat_per_ticket | I2: • Free (free tickets): +0.0 — Up to 5,000 free tickets/year, no fee — First 5 paid sales also free • Pay as you go (PAYG): +0.6 — All features, flat fee per usage, no subscription — Stripe: deducted at sale; PayPal/Square: billed to card • Pre-pay credits: — Same features; lower unit price when credits are bought in advance — See prepaid bundles; credits never expire; running out falls back to PAYG automatically; minimum bundle 100 credits | J2: • 500 credits: 0.41 (срок: none; возврат: None) • largest bundles: 0.22 (срок: none; возврат: None) | K2: включён: False; свой процессинг: True; Stripe, PayPal, Square; Stripe UK 1.5% + GBP 0.20 (example) | L2: configurable (organizer adds own booking/transaction fee; default is organizer absorbs) | M2: Free tickets are free up to 5,000/year; first 5 paid tickets free. | N2: Seat reservation costs 1 extra usage per seated ticket: PAYG +GBP 0.60 (a paid seated ticket = GBP 1.20); pre-pay: +1 credit. A free seated ticket still costs 1 usage. Charity discount applies; marking seats not-for-sale is free. | O2: Immediate into organizer's Stripe/PayPal/Square; no payout by TT. | P2: No refund of TT fee/credit on refund or cancel; processor fees usually not returned either. No TT chargeback fee found on pages read. | Q2: TT fees shown excl. VAT; VAT/sales tax added where applicable | R2: • Charged per 'usage', not on ticket price: paid ticket = 1 usage; seated paid ticket = 2; free ticket = 0; free seated ticket = 1; product sale = 1; ticket issued via API (even free) = 1; imported ticket (even free) = 1; every ticket in a paid bundle = 1; a voucher-covered order is still charged. • First 5 ticket sales are free; the standard rate starts from the sixth paid ticket (pricing page FAQ). • Free tickets free within fair usage: the pricing page says 5,000 free tickets/year but its FAQ also mentions 'more than 2,000' in another answer; above fair usage TT gives a per-free-ticket quote via support. • Fees are not refunded when a ticket is refunded or cancelled (credits/PAYG fee kept); order transfer is free. • Discounts (apply via billing page, at TT's discretion): 50% for registered charities (forever), 20% for B Corps/PTAs/CICs/non-profits/BBN, half-usage for tickets under 5 incl. booking fees (a seated 5 ticket = 1.5 usage), 50% for Music Venue Trust members, 50% for Round Tables, 6 months free for Art Tickets users. Only one discount at a time; none applies to white-label/custom-domain prices or processor fees. • Refund protection: buyers can add it for 8% of ticket price; organizer keeps 10% of that fee, rest goes to TT (collected via PAYG). • SMS/WhatsApp reminders: TT charges 0.10 per event per order (GBP/USD) for buyers who opt in; organizer keeps any excess of the suggested fee. • TT does not touch the payment: Stripe, PayPal, Square or offline needed; TT fees are on top of processor fees; credits do not cover processing. • VAT and sales tax charged on TT fees where applicable; TT prices are shown excl. VAT. • No subscription, no contract; credits never expire; credits can be transferred between the organizer's box offices. • Pass-on of fees is manual: organizer adds a booking fee (per ticket) and/or transaction fee (per order, % and/or fixed); no automatic 'pass all fees' toggle. TT warns US sellers about the FTC junk-fees rule. • GBP bundle table: only the 500-credit (GBP 0.41) and 'from GBP 0.22' figures were readable. | S2: • {"name": "White label (logo removal + custom domain)", "price": "GBP 39/month; custom domain alone GBP 7/month"} • {"name": "HubSpot/ActiveCampaign/Constant Contact integrations", "price": "monthly fee shown in account (amount not public)"} • {"name": "Free check-in app", "price": "free"} | T2: Very large free events / above fair usage: ask support for a quote; 'Book a demo' for larger organizers (no public enterprise price) | U2: self-serve, small/mid organizers (shows, workshops, venues, charities); flat fee per ticket, bring-your-own processor | V2: page | W2: https://www.tickettailor.com/pricing (pricing page + FAQ) https://help.tickettailor.com/en/articles/6731528-how-much-does-ticket-tailor-cost-and-how-will-i-be-charged (help centre: how much does TT cost) https://help.tickettailor.com/en/articles/4096561-what-are-the-fees-for-using-seating-charts (help centre: seating chart fees) https://help.tickettailor.com/en/articles/4725866-how-do-pre-pay-ticket-credits-work (help centre: pre-pay credits) https://help.tickettailor.com/en/articles/8687492-what-discounts-do-we-offer (help centre: discounts) https://help.tickettailor.com/en/articles/5210356-how-to-pass-fees-onto-your-ticket-buyers (help centre: passing fees on)
A3: Глобальные self-serve | B3: Ticket Tailor | C3: https://www.tickettailor.com | D3: US | E3: USD | F3: direct merchant | G3: Direct merchant: buyer pays straight into the organizer's own Stripe/PayPal/Square account (revenue appears almost immediately, bank transfer takes about a week); TT never holds the money. TT fee collection: Pre-pay = card charged immediately when credits are bought (optional auto top-up monthly or when <=25 credits left). PAYG on Stripe = fee deducted automatically at the point of sale; PAYG on PayPal/Square/offline = TT charges the organizer's card on file monthly, or every 50 usage units, or 2 days after the last event ends. | H3: flat_per_ticket | I3: • Free (free tickets): +0.0 — Up to 5,000 free tickets/year, no fee — First 5 paid sales also free • Pay as you go (PAYG): +0.85 — All features, flat fee per usage, no subscription — Stripe: deducted at sale; PayPal/Square: billed to card • Pre-pay credits: — Same features; lower unit price when credits are bought in advance — See prepaid bundles; credits never expire; running out falls back to PAYG automatically; minimum bundle 100 credits | J3: • 100 credits: 0.7 (срок: none; возврат: None) • 500 credits: 0.6 (срок: none; возврат: None) • 1,000 credits: 0.52 (срок: none; возврат: None) • 5,000 credits: 0.43 (срок: none; возврат: None) • 10,000 credits: 0.39 (срок: none; возврат: None) • 20,000+ credits: 0.34 (срок: none; возврат: None) | K3: включён: False; свой процессинг: True; Stripe, PayPal, Square; Stripe US 2.9% + $0.30 (example) | L3: configurable (organizer adds own booking/transaction fee; default is organizer absorbs) | M3: Free tickets are free up to 5,000/year; first 5 paid tickets free. | N3: Seat reservation: PAYG +$0.85 per seated ticket (paid seated ticket = $1.70); pre-pay: +1 credit. | O3: Immediate into organizer's Stripe/PayPal/Square; no payout by TT. | P3: No refund of TT fee/credit on refund or cancel; processor fees usually not returned either. No TT chargeback fee found on pages read. | Q3: TT fees shown excl. VAT; VAT/sales tax added where applicable | R3: • Charged per 'usage', not on ticket price: paid ticket = 1 usage; seated paid ticket = 2; free ticket = 0; free seated ticket = 1; product sale = 1; ticket issued via API (even free) = 1; imported ticket (even free) = 1; every ticket in a paid bundle = 1; a voucher-covered order is still charged. • First 5 ticket sales are free; the standard rate starts from the sixth paid ticket (pricing page FAQ). • Free tickets free within fair usage: the pricing page says 5,000 free tickets/year but its FAQ also mentions 'more than 2,000' in another answer; above fair usage TT gives a per-free-ticket quote via support. • Fees are not refunded when a ticket is refunded or cancelled (credits/PAYG fee kept); order transfer is free. • Discounts (apply via billing page, at TT's discretion): 50% for registered charities (forever), 20% for B Corps/PTAs/CICs/non-profits/BBN, half-usage for tickets under 5 incl. booking fees (a seated 5 ticket = 1.5 usage), 50% for Music Venue Trust members, 50% for Round Tables, 6 months free for Art Tickets users. Only one discount at a time; none applies to white-label/custom-domain prices or processor fees. • Refund protection: buyers can add it for 8% of ticket price; organizer keeps 10% of that fee, rest goes to TT (collected via PAYG). • SMS/WhatsApp reminders: TT charges 0.10 per event per order (GBP/USD) for buyers who opt in; organizer keeps any excess of the suggested fee. • TT does not touch the payment: Stripe, PayPal, Square or offline needed; TT fees are on top of processor fees; credits do not cover processing. • VAT and sales tax charged on TT fees where applicable; TT prices are shown excl. VAT. • No subscription, no contract; credits never expire; credits can be transferred between the organizer's box offices. • Pass-on of fees is manual: organizer adds a booking fee (per ticket) and/or transaction fee (per order, % and/or fixed); no automatic 'pass all fees' toggle. TT warns US sellers about the FTC junk-fees rule. • US credit tiers come from a competitor's (TixFox) reading of TT's USD calculator on 2026-10-08, not from a statically rendered TT page; TT's own headline says credits start 'from $0.30'. | S3: • {"name": "White label (logo removal + custom domain)", "price": "$49/month; custom domain alone $8/month"} • {"name": "HubSpot/ActiveCampaign/Constant Contact integrations", "price": "monthly fee shown in account (amount not public)"} • {"name": "Free check-in app", "price": "free"} | T3: Very large free events / above fair usage: ask support for a quote; 'Book a demo' for larger organizers (no public enterprise price) | U3: self-serve, small/mid organizers (shows, workshops, venues, charities); flat fee per ticket, bring-your-own processor | V3: third_party | W3: https://www.tickettailor.com/pricing (pricing page + FAQ) https://help.tickettailor.com/en/articles/6731528-how-much-does-ticket-tailor-cost-and-how-will-i-be-charged (help centre: how much does TT cost) https://help.tickettailor.com/en/articles/4096561-what-are-the-fees-for-using-seating-charts (help centre: seating chart fees) https://help.tickettailor.com/en/articles/4725866-how-do-pre-pay-ticket-credits-work (help centre: pre-pay credits) https://help.tickettailor.com/en/articles/8687492-what-discounts-do-we-offer (help centre: discounts) https://help.tickettailor.com/en/articles/5210356-how-to-pass-fees-onto-your-ticket-buyers (help centre: passing fees on) https://tixfox.co/blog/ticket-tailor-fees (third-party (TixFox) read of US credit tiers)
A4: Глобальные self-serve | B4: Ticket Tailor | C4: https://www.tickettailor.com | D4: Eurozone | E4: EUR | F4: direct merchant | G4: Direct merchant: buyer pays straight into the organizer's own Stripe/PayPal/Square account (revenue appears almost immediately, bank transfer takes about a week); TT never holds the money. TT fee collection: Pre-pay = card charged immediately when credits are bought (optional auto top-up monthly or when <=25 credits left). PAYG on Stripe = fee deducted automatically at the point of sale; PAYG on PayPal/Square/offline = TT charges the organizer's card on file monthly, or every 50 usage units, or 2 days after the last event ends. | H4: flat_per_ticket | I4: • Free (free tickets): +0.0 — Up to 5,000 free tickets/year, no fee — First 5 paid sales also free • Pay as you go (PAYG): +0.7 — All features, flat fee per usage, no subscription — Stripe: deducted at sale; PayPal/Square: billed to card • Pre-pay credits: — Same features; lower unit price when credits are bought in advance — See prepaid bundles; credits never expire; running out falls back to PAYG automatically; minimum bundle 100 credits | J4: • credit bundles: 0.3 (срок: none; возврат: None) | K4: включён: False; свой процессинг: True; Stripe, PayPal, Square; Stripe Eurozone 1.5% + EUR 0.25 (example) | L4: configurable (organizer adds own booking/transaction fee; default is organizer absorbs) | M4: Free tickets are free up to 5,000/year; first 5 paid tickets free. | N4: Seat reservation: PAYG +EUR 0.70 per seated ticket; pre-pay: +1 credit. | O4: Immediate into organizer's Stripe/PayPal/Square; no payout by TT. | P4: No refund of TT fee/credit on refund or cancel; processor fees usually not returned either. No TT chargeback fee found on pages read. | Q4: TT fees shown excl. VAT; VAT/sales tax added where applicable | R4: • Charged per 'usage', not on ticket price: paid ticket = 1 usage; seated paid ticket = 2; free ticket = 0; free seated ticket = 1; product sale = 1; ticket issued via API (even free) = 1; imported ticket (even free) = 1; every ticket in a paid bundle = 1; a voucher-covered order is still charged. • First 5 ticket sales are free; the standard rate starts from the sixth paid ticket (pricing page FAQ). • Free tickets free within fair usage: the pricing page says 5,000 free tickets/year but its FAQ also mentions 'more than 2,000' in another answer; above fair usage TT gives a per-free-ticket quote via support. • Fees are not refunded when a ticket is refunded or cancelled (credits/PAYG fee kept); order transfer is free. • Discounts (apply via billing page, at TT's discretion): 50% for registered charities (forever), 20% for B Corps/PTAs/CICs/non-profits/BBN, half-usage for tickets under 5 incl. booking fees (a seated 5 ticket = 1.5 usage), 50% for Music Venue Trust members, 50% for Round Tables, 6 months free for Art Tickets users. Only one discount at a time; none applies to white-label/custom-domain prices or processor fees. • Refund protection: buyers can add it for 8% of ticket price; organizer keeps 10% of that fee, rest goes to TT (collected via PAYG). • SMS/WhatsApp reminders: TT charges 0.10 per event per order (GBP/USD) for buyers who opt in; organizer keeps any excess of the suggested fee. • TT does not touch the payment: Stripe, PayPal, Square or offline needed; TT fees are on top of processor fees; credits do not cover processing. • VAT and sales tax charged on TT fees where applicable; TT prices are shown excl. VAT. • No subscription, no contract; credits never expire; credits can be transferred between the organizer's box offices. • Pass-on of fees is manual: organizer adds a booking fee (per ticket) and/or transaction fee (per order, % and/or fixed); no automatic 'pass all fees' toggle. TT warns US sellers about the FTC junk-fees rule. | S4: • {"name": "White label (logo removal + custom domain)", "price": "EUR 45/month; custom domain alone EUR 8/month"} • {"name": "HubSpot/ActiveCampaign/Constant Contact integrations", "price": "monthly fee shown in account (amount not public)"} • {"name": "Free check-in app", "price": "free"} | T4: Very large free events / above fair usage: ask support for a quote; 'Book a demo' for larger organizers (no public enterprise price) | U4: self-serve, small/mid organizers (shows, workshops, venues, charities); flat fee per ticket, bring-your-own processor | V4: page | W4: https://www.tickettailor.com/pricing (pricing page + FAQ) https://help.tickettailor.com/en/articles/6731528-how-much-does-ticket-tailor-cost-and-how-will-i-be-charged (help centre: how much does TT cost) https://help.tickettailor.com/en/articles/4096561-what-are-the-fees-for-using-seating-charts (help centre: seating chart fees) https://help.tickettailor.com/en/articles/4725866-how-do-pre-pay-ticket-credits-work (help centre: pre-pay credits) https://help.tickettailor.com/en/articles/8687492-what-discounts-do-we-offer (help centre: discounts) https://help.tickettailor.com/en/articles/5210356-how-to-pass-fees-onto-your-ticket-buyers (help centre: passing fees on)
A5: Глобальные self-serve | B5: Ticket Tailor | C5: https://www.tickettailor.com | D5: Australia | E5: AUD | F5: direct merchant | G5: Direct merchant: buyer pays straight into the organizer's own Stripe/PayPal/Square account (revenue appears almost immediately, bank transfer takes about a week); TT never holds the money. TT fee collection: Pre-pay = card charged immediately when credits are bought (optional auto top-up monthly or when <=25 credits left). PAYG on Stripe = fee deducted automatically at the point of sale; PAYG on PayPal/Square/offline = TT charges the organizer's card on file monthly, or every 50 usage units, or 2 days after the last event ends. | H5: flat_per_ticket | I5: • Free (free tickets): +0.0 — Up to 5,000 free tickets/year, no fee — First 5 paid sales also free • Pay as you go (PAYG): +1.1 — All features, flat fee per usage, no subscription — Stripe: deducted at sale; PayPal/Square: billed to card • Pre-pay credits: — Same features; lower unit price when credits are bought in advance — See prepaid bundles; credits never expire; running out falls back to PAYG automatically; minimum bundle 100 credits | J5: • credit bundles: None (срок: none; возврат: None) | K5: включён: False; свой процессинг: True; Stripe, PayPal, Square; Stripe AU 1.75% + A$0.30 (example) | L5: configurable (organizer adds own booking/transaction fee; default is organizer absorbs) | M5: Free tickets are free up to 5,000/year; first 5 paid tickets free. | N5: Seat reservation: PAYG +A$1.10 per seated ticket; pre-pay: +1 credit. | O5: Immediate into organizer's Stripe/PayPal/Square; no payout by TT. | P5: No refund of TT fee/credit on refund or cancel; processor fees usually not returned either. No TT chargeback fee found on pages read. | Q5: TT fees shown excl. VAT; VAT/sales tax added where applicable | R5: • Charged per 'usage', not on ticket price: paid ticket = 1 usage; seated paid ticket = 2; free ticket = 0; free seated ticket = 1; product sale = 1; ticket issued via API (even free) = 1; imported ticket (even free) = 1; every ticket in a paid bundle = 1; a voucher-covered order is still charged. • First 5 ticket sales are free; the standard rate starts from the sixth paid ticket (pricing page FAQ). • Free tickets free within fair usage: the pricing page says 5,000 free tickets/year but its FAQ also mentions 'more than 2,000' in another answer; above fair usage TT gives a per-free-ticket quote via support. • Fees are not refunded when a ticket is refunded or cancelled (credits/PAYG fee kept); order transfer is free. • Discounts (apply via billing page, at TT's discretion): 50% for registered charities (forever), 20% for B Corps/PTAs/CICs/non-profits/BBN, half-usage for tickets under 5 incl. booking fees (a seated 5 ticket = 1.5 usage), 50% for Music Venue Trust members, 50% for Round Tables, 6 months free for Art Tickets users. Only one discount at a time; none applies to white-label/custom-domain prices or processor fees. • Refund protection: buyers can add it for 8% of ticket price; organizer keeps 10% of that fee, rest goes to TT (collected via PAYG). • SMS/WhatsApp reminders: TT charges 0.10 per event per order (GBP/USD) for buyers who opt in; organizer keeps any excess of the suggested fee. • TT does not touch the payment: Stripe, PayPal, Square or offline needed; TT fees are on top of processor fees; credits do not cover processing. • VAT and sales tax charged on TT fees where applicable; TT prices are shown excl. VAT. • No subscription, no contract; credits never expire; credits can be transferred between the organizer's box offices. • Pass-on of fees is manual: organizer adds a booking fee (per ticket) and/or transaction fee (per order, % and/or fixed); no automatic 'pass all fees' toggle. TT warns US sellers about the FTC junk-fees rule. | S5: • {"name": "White label (logo removal + custom domain)", "price": "A$69/month; custom domain alone A$12/month"} • {"name": "HubSpot/ActiveCampaign/Constant Contact integrations", "price": "monthly fee shown in account (amount not public)"} • {"name": "Free check-in app", "price": "free"} | T5: Very large free events / above fair usage: ask support for a quote; 'Book a demo' for larger organizers (no public enterprise price) | U5: self-serve, small/mid organizers (shows, workshops, venues, charities); flat fee per ticket, bring-your-own processor | V5: page | W5: https://www.tickettailor.com/pricing (pricing page + FAQ) https://help.tickettailor.com/en/articles/6731528-how-much-does-ticket-tailor-cost-and-how-will-i-be-charged (help centre: how much does TT cost) https://help.tickettailor.com/en/articles/4096561-what-are-the-fees-for-using-seating-charts (help centre: seating chart fees) https://help.tickettailor.com/en/articles/4725866-how-do-pre-pay-ticket-credits-work (help centre: pre-pay credits) https://help.tickettailor.com/en/articles/8687492-what-discounts-do-we-offer (help centre: discounts) https://help.tickettailor.com/en/articles/5210356-how-to-pass-fees-onto-your-ticket-buyers (help centre: passing fees on)
A6: Глобальные self-serve | B6: Ticket Tailor | C6: https://www.tickettailor.com | D6: Canada | E6: CAD | F6: direct merchant | G6: Direct merchant: buyer pays straight into the organizer's own Stripe/PayPal/Square account (revenue appears almost immediately, bank transfer takes about a week); TT never holds the money. TT fee collection: Pre-pay = card charged immediately when credits are bought (optional auto top-up monthly or when <=25 credits left). PAYG on Stripe = fee deducted automatically at the point of sale; PAYG on PayPal/Square/offline = TT charges the organizer's card on file monthly, or every 50 usage units, or 2 days after the last event ends. | H6: flat_per_ticket | I6: • Free (free tickets): +0.0 — Up to 5,000 free tickets/year, no fee — First 5 paid sales also free • Pay as you go (PAYG): +1.0 — All features, flat fee per usage, no subscription — Stripe: deducted at sale; PayPal/Square: billed to card • Pre-pay credits: — Same features; lower unit price when credits are bought in advance — See prepaid bundles; credits never expire; running out falls back to PAYG automatically; minimum bundle 100 credits | J6: • credit bundles: None (срок: none; возврат: None) | K6: включён: False; свой процессинг: True; Stripe, PayPal, Square; Stripe CA 2.9% + C$0.30 (example) | L6: configurable (organizer adds own booking/transaction fee; default is organizer absorbs) | M6: Free tickets are free up to 5,000/year; first 5 paid tickets free. | N6: Seat reservation: PAYG +C$1.00 per seated ticket; pre-pay: +1 credit. | O6: Immediate into organizer's Stripe/PayPal/Square; no payout by TT. | P6: No refund of TT fee/credit on refund or cancel; processor fees usually not returned either. No TT chargeback fee found on pages read. | Q6: TT fees shown excl. VAT; VAT/sales tax added where applicable | R6: • Charged per 'usage', not on ticket price: paid ticket = 1 usage; seated paid ticket = 2; free ticket = 0; free seated ticket = 1; product sale = 1; ticket issued via API (even free) = 1; imported ticket (even free) = 1; every ticket in a paid bundle = 1; a voucher-covered order is still charged. • First 5 ticket sales are free; the standard rate starts from the sixth paid ticket (pricing page FAQ). • Free tickets free within fair usage: the pricing page says 5,000 free tickets/year but its FAQ also mentions 'more than 2,000' in another answer; above fair usage TT gives a per-free-ticket quote via support. • Fees are not refunded when a ticket is refunded or cancelled (credits/PAYG fee kept); order transfer is free. • Discounts (apply via billing page, at TT's discretion): 50% for registered charities (forever), 20% for B Corps/PTAs/CICs/non-profits/BBN, half-usage for tickets under 5 incl. booking fees (a seated 5 ticket = 1.5 usage), 50% for Music Venue Trust members, 50% for Round Tables, 6 months free for Art Tickets users. Only one discount at a time; none applies to white-label/custom-domain prices or processor fees. • Refund protection: buyers can add it for 8% of ticket price; organizer keeps 10% of that fee, rest goes to TT (collected via PAYG). • SMS/WhatsApp reminders: TT charges 0.10 per event per order (GBP/USD) for buyers who opt in; organizer keeps any excess of the suggested fee. • TT does not touch the payment: Stripe, PayPal, Square or offline needed; TT fees are on top of processor fees; credits do not cover processing. • VAT and sales tax charged on TT fees where applicable; TT prices are shown excl. VAT. • No subscription, no contract; credits never expire; credits can be transferred between the organizer's box offices. • Pass-on of fees is manual: organizer adds a booking fee (per ticket) and/or transaction fee (per order, % and/or fixed); no automatic 'pass all fees' toggle. TT warns US sellers about the FTC junk-fees rule. | S6: • {"name": "White label (logo removal + custom domain)", "price": "C$69/month; custom domain alone C$10/month"} • {"name": "HubSpot/ActiveCampaign/Constant Contact integrations", "price": "monthly fee shown in account (amount not public)"} • {"name": "Free check-in app", "price": "free"} | T6: Very large free events / above fair usage: ask support for a quote; 'Book a demo' for larger organizers (no public enterprise price) | U6: self-serve, small/mid organizers (shows, workshops, venues, charities); flat fee per ticket, bring-your-own processor | V6: page | W6: https://www.tickettailor.com/pricing (pricing page + FAQ) https://help.tickettailor.com/en/articles/6731528-how-much-does-ticket-tailor-cost-and-how-will-i-be-charged (help centre: how much does TT cost) https://help.tickettailor.com/en/articles/4096561-what-are-the-fees-for-using-seating-charts (help centre: seating chart fees) https://help.tickettailor.com/en/articles/4725866-how-do-pre-pay-ticket-credits-work (help centre: pre-pay credits) https://help.tickettailor.com/en/articles/8687492-what-discounts-do-we-offer (help centre: discounts) https://help.tickettailor.com/en/articles/5210356-how-to-pass-fees-onto-your-ticket-buyers (help centre: passing fees on)
